<mujoco model="LWR">
  <compiler inertiafromgeom="true" />
  <default>
    <joint limited='true' damping='1' armature='0'  />
		<geom contype="0" friction="1 0.1 0.1" rgba="0.7 0.7 0 1" />
		<tendon />
		<motor ctrlrange="-3 3"/>
  </default>
  <option	timestep="0.02" gravity="0 0 -9.81" />
  <asset>
    <mesh file="LWR_Base1a_b.stl"/>
    <mesh file="LWR_Base1b_b.stl"/>
    <mesh file="LWR_Link1a_b.stl"/>
    <mesh file="LWR_Link1b_b.stl"/>
  </asset>

  <worldbody>
		<geom name="ground" type="plane" contype="1" pos="0 0 -0.001" size="4 4 4" rgba="0.9 0.9 0.9 1"/>
      
    <geom type="mesh" rgba = "0.9 0.4 0.1 1" contype="0" mesh="LWR_Base1a_b.stl" />
    <geom type="mesh" rgba = "0.8 0.8 0.8 1" contype="0" mesh="LWR_Base1b_b.stl" />

    <!--  ================= ARM ================= /-->
    <body name="link1" pos="0 0 0" >
      <joint name="joint1" type="hinge" pos="0 0 0" axis="0 0 1" range="-177 177"/>
      <geom type="mesh" rgba = "0.9 0.4 0.1 1" mesh="LWR_Link1a_b.stl" />
      <geom type="mesh" rgba = "0.8 0.8 0.8 1" mesh="LWR_Link1b_b.stl" />
      
<!--
      <body name="link2" pos="0 0 0.31" >
        <joint name="joint2" type="hinge" pos="0 0 0" axis="1 0 0" range="-91 91"/>
        <geom type="mesh" meshpos="0 0 -0.31" meshquat="1 0 0 0"  meshscale="0.1 0.1 0.1" rgba = "0.9 0.4 0.1 1" mindist="0.01" meshfile="LWR_Link2a_b.stl" />
        <geom type="mesh" meshpos="0 0 -0.31" meshquat="1 0 0 0"  meshscale="0.1 0.1 0.1" rgba = "0.8 0.8 0.8 1" meshfile="LWR_Link2b_b.stl" />

        <body name="link3" pos="0 0 0.2" >
            <joint name="joint3" type="hinge" pos="0 0 0" axis="0 0 1" range="-174 174"/>
            <geom type="mesh" meshpos="0 0 -0.51" meshquat="1 0 0 0"  meshscale="0.1 0.1 0.1" rgba = "0.9 0.4 0.1 1" mindist="0.01" meshfile="LWR_Link3a_b.stl" />
            <geom type="mesh" meshpos="0 0 -0.51" meshquat="1 0 0 0"  meshscale="0.1 0.1 0.1" rgba = "0.8 0.8 0.8 1"meshfile="LWR_Link3b_b.stl" />

          <body name="link4" pos="0 0 0.2" >
            <joint name="joint4" type="hinge" pos="0 0 0" axis="1 0 0" range="-137 137"/>
            <geom type="mesh" meshpos="0 0 -0.71" meshquat="1 0 0 0"  meshscale="0.1 0.1 0.1" rgba = "0.9 0.4 0.1 1"meshfile="LWR_Link4a_b.stl" />
            <geom type="mesh" meshpos="0 0 -0.71" meshquat="1 0 0 0"  meshscale="0.1 0.1 0.1" rgba = "0.8 0.8 0.8 1"meshfile="LWR_Link4b_b.stl" />
            
            <body name="link5" pos="0 0 0.2" >
              <joint name="joint5" type="hinge" pos="0 0 0" axis="0 0 1" range="-255 255"/>
              <geom type="mesh" meshpos="0 0 -0.91" meshquat="1 0 0 0"  meshscale="0.1 0.1 0.1" rgba = "0.9 0.4 0.1 1" mindist="0.01" meshfile="LWR_Link5a_b.stl" />
        
              <body name="link6" pos="0 0 0.19" >
                  <joint name="joint6" type="hinge" pos="0 0 0" axis="1 0 0" range="-165 165"/>
                  <geom type="mesh" meshpos="0 0 -1.1" meshquat="1 0 0 0"  meshscale="0.1 0.1 0.1" rgba = "0.9 0.4 0.1 1" mindist="0.01" meshfile="LWR_Link6a_b.stl" />
                  <geom type="mesh" meshpos="0 0 -1.1" meshquat="1 0 0 0"  contype="1"  meshscale="0.1 0.1 0.1" rgba = "0.2 0.2 0.2 1" mindist="0.01" meshfile="LWR_Link7a_b.stl" />

                <body name="link7" pos="0 0 0.078" >
                  <joint name="joint7" type="hinge" pos="0 0 0" axis="0 0 1" range="-360 360"/>
                </body>
              </body>
            </body>
          </body>
        </body>
      </body>
-->
    </body>
  </worldbody>
    
  <actuator >
    <motor name="a_joint1" joint="joint1" gear="1"/>
    <motor name="a_joint2" joint="joint2" gear="1"/>
    <motor name="a_joint3" joint="joint3" gear="1"/>
    <motor name="a_joint4" joint="joint4" gear="1"/>
    <motor name="a_joint5" joint="joint5" gear="1"/>
    <motor name="a_joint6" joint="joint6" gear="1"/>
    <motor name="a_joint7" joint="joint7" gear="1"/>
  </actuator>
</mujoco>

