<!-- ======================================================
	MuJoCo model
	
	Model   : Kuka LWR arm - body chain
	Author  : Aljaz Kramberger

	Copyright 2020 SDU 

====================================================== -->

<mujocoinclude>
	<!--	================= LWR ARM ================= /-->
	<body name="LWR" pos="0 0 0" quat="1 0 0 0" childclass="LWR">
		<inertial pos="0 0 0.1000" quat="1 0 0 0" mass="2.3562" diaginertia="0.0093 0.0093 0.0029" />
		<geom type="mesh" contype="0" mesh="LWR_Base1a_b" />
		<geom type="mesh" pos="0 0 -0.001" material="LWR_silver" contype="0" mesh="LWR_Base1b_b" />

		<body name="LWR/link1" pos="0 0 0.11" quat="0.707107 0 0 -0.707107" >
			<inertial pos="0 0 0.1000" quat="1 0 0 0" mass="2.3562" diaginertia="0.0093 0.0093 0.0029" />
			<joint name="LWR/joint1" type="hinge" pos="0 0 0" axis="0 0 1" range="-2.9671 2.9671"/>
			<geom type="mesh" pos="0 0 -0.11" mesh="LWR_Link1a_b" />
			<geom type="mesh" pos="0 0 -0.11" material="LWR_silver" mesh="LWR_Link1b_b" />
		
			<body name="LWR/link2" pos="0 0 0.2" >
				<inertial pos="0 0 0.1000" quat="1 0 0 0" mass="2.9452" diaginertia="0.0172 0.0172 0.0037" />
				<joint name="LWR/joint2" type="hinge" pos="0 0 0" axis="1 0 0" range="-2.0944 2.0944"/>
				<geom type="mesh" pos="0 0 -0.31" mesh="LWR_Link2a_b" />
				<geom type="mesh" pos="0 0 -0.31" material="LWR_silver" mesh="LWR_Link2b_b" />

				<body name="LWR/link3" pos="0 0 0.2" quat="0 0 0 1" >
					<inertial pos="0 0 0.1000" quat="1 0 0 0" mass="2.9452" diaginertia="0.0172 0.0172 0.0037" />
					<joint name="LWR/joint3" type="hinge" pos="0 0 0" axis="0 0 1" range="-2.9671 2.9671"/>
					<geom type="mesh" pos="0 0 -0.51" quat="1 0 0 0"	mesh="LWR_Link3a_b" />
					<geom type="mesh" pos="0 0 -0.51" quat="1 0 0 0"	material="LWR_silver" mesh="LWR_Link3b_b" />

					<body name="LWR/link4" pos="0 0 0.2" >
						<inertial pos="0 0 0.1000" quat="1 0 0 0" mass="2.9452" diaginertia="0.0172 0.0172 0.0037" />
						<joint name="LWR/joint4" type="hinge" pos="0 0 0" axis="1 0 0" range="-2.0944 2.0944"/>
						<geom type="mesh" pos="0 0 -0.71" quat="1 0 0 0"	mesh="LWR_Link4a_b" />
						<geom type="mesh" pos="0 0 -0.71" quat="1 0 0 0"	material="LWR_silver" mesh="LWR_Link4b_b" />
					
						<body name="LWR/link5" pos="0 0 0.2" quat="0 0 0 1" >
							<inertial pos="0 0 0.0950" quat="1 0 0 0" mass="2.8274" diaginertia="0.0153 0.0153 0.0035" />
							<joint name="LWR/joint5" type="hinge" pos="0 0 0" axis="0 0 1" range="-2.9671    2.9671"/>
							<geom type="mesh" pos="0 0 -0.91" quat="1 0 0 0"	mesh="LWR_Link5a_b" />
			
							<body name="LWR/link6" pos="0 0 0.19" >
								<inertial pos="0 0 0.0190" quat="1 0 0 0" mass="1.0367" diaginertia="0.0013 0.0013 0.0013" />
								<joint name="LWR/joint6" type="hinge" pos="0 0 0" axis="1 0 0" range="-2.0944 2.0944"/>
								<geom type="mesh" pos="0 0 -1.1" quat="1 0 0 0"	material="LWR_silver" mesh="LWR_Link6a_b" />

								<body name="LWR/link7" pos="0 0 0.078" >
									<inertial pos="0 0 0.0200" quat="1 0 0 0" mass="0.6032" diaginertia="0.0006 0.0006 0.0005" />
									<joint name="LWR/joint7" type="hinge" pos="0 0 0" axis="0 0 1" range="-2.9671 2.9671"/>
									<geom type="mesh" pos="0 0 -1.178" quat="1 0 0 0"	rgba = "0.2 0.2 0.2 1" mesh="LWR_Link7a_b" />
									<site name="LWR/EE" pos="0 0 0" />
								</body>
							</body>
						</body>
					</body>
				</body>
			</body>
		</body>
	</body>
</mujocoinclude>

