<!-- ======================================================
	MuJoCo model
	
	Model   : PA10 gripper - body chain
	Author  : Aljaz Kramberger

	Copyright 2020 SDU 


====================================================== -->

<mujocoinclude>
		<!--	================= GRIPPER ================= /-->
		<body pos="0 0 0" childclass="gripper">
			<geom group="1" type="cylinder" fromto="0 0 0 0 0 0.079" size="0.04"/>

			<body pos="0 0 0.08" >
				<joint name="gripper_1" type="slide" pos="0 0 0" axis="1 0 0" limited="true" range="0.001 0.05"/>
				<geom group="1"  type="box" pos="0.005  0.0125 0.03" size="0.0045 0.001 0.03"/>
				<geom group="1"  type="box" pos="0.005 -0.0125 0.03" size="0.0045 0.001 0.03"/>
				<geom group="1"  type="box" pos="0.01  0    0.03" size="0.001 0.0135 0.03"/>
			</body>
			<body pos="0 0 0.08" >
				<joint name="gripper_2" type="slide" pos="0 0 0" axis="1 0 0" limited="true" range="-0.05 0.001"/>
				<geom group="1"  type="box" pos="-0.005  0.0125 0.03" size="0.0045 0.001 0.03"/>
				<geom group="1"  type="box" pos="-0.005 -0.0125 0.03" size="0.0045 0.001 0.03"/>
				<geom group="1"  type="box" pos="-0.01  0    0.03" size="0.001 0.0135 0.03"/>
			</body>
		</body>
</mujocoinclude>